Workbook

Sheet Slik bruker du malen
A1: QPSNordic 34+ – svarregistrering
A3: Registrer svarene fra papirskjemaene på arket «Svar»: én rad per skjema, ett tall fra 1 til 5 per spørsmål. La cellen stå tom hvis spørsmålet ikke er besvart. Arket «Oppsummering» regner ut resten.
A4: Før dere ser på tallene
A6: • Veiledningen anbefaler ikke statistiske analyser for grupper under 10 personer. Oppsummeringen viser derfor ingenting før minst 10 har svart.
A7: • For 10–20 personer anbefales middelverdi og median, og svarene slått sammen til tre kategorier: 1–2, 3 og 4–5. Det er det oppsummeringen viser.
A8: • Kortversjonen har ingen skalaer, og testingen av validitet og reliabilitet gjelder ikke for den. Se på spørsmålene ett og ett.
A9: • Ikke registrer navn eller noe annet som kan knytte et skjema til en person. Oppbevar papirskjemaene innelåst, og makuler dem når svarene er registrert.
A10: • Høy verdi betyr «ofte» eller «mye» – det er bra på noen spørsmål (for eksempel nr. 17, støtte fra kollegaer) og dårlig på andre (for eksempel nr. 2, for mye å gjøre).
A11: Kilde: Skogstad, A., Knardahl, S., Lindström, K., Elo, A.-L., Dallner, M., Gamberale, F., Hottinen, V. og Ørhede, E. (2001). Brukerveiledning QPSNordic. Generelt spørreskjema for psykologiske og sosiale faktorer i arbeid. STAMI-rapport årg. 2, nr. 1. Oslo: Statens arbeidsmiljøinstitutt. Vedlegg 2, s. 36–38.
A13: Laget av Orgpuls · orgpuls.no · Fri til bruk i egen virksomhet. Malen er et hjelpemiddel, ikke juridisk rådgivning.

Sheet Svar
A1: Svar
A2: Én rad per skjema. Tall fra 1 til 5; tomt hvis ubesvart.
A4: Skjema | B4: 1. Er arbeidsmengden din ujevn slik at den hoper seg opp? | C4: 2. Har du for mye å gjøre? | D4: 3. Er arbeidsoppgavene for vanskelige for deg? | E4: 4. Utfører du arbeidsoppgaver som du trenger mer opplæring for å gjøre? | F4: 5. Er dine spesialkunnskaper og ferdigheter nyttige i arbeidet ditt? | G4: 6. Er arbeidet ditt utfordrende på en positiv måte? | H4: 7. Er det fastsatt klare mål for din jobb? | I4: 8. Vet du nøyaktig hva som forventes av deg i jobben? | J4: 9. Mottar du motstridende forespørsler fra to eller flere personer? | K4: 10. Kan du påvirke mengden av arbeid som blir tildelt deg? | L4: 11. Kan du selv bestemme ditt arbeidstempo? | M4: 12. Kan du selv bestemme når du skal ta pauser? | N4: 13. Kan du påvirke beslutninger som er viktige for ditt arbeid? | O4: 14. Vet du hva slags oppgaver du kan få en måned frem i tiden? | P4: 15. Går det rykter om forandringer på din arbeidsplass? | Q4: 16. Er du fornøyd med din evne til å løse problemer som dukker opp i arbeidet? | R4: 17. Om du trenger det, kan du få støtte og hjelp i ditt arbeid fra dine kollegaer? | S4: 18. Om du trenger det, kan du få støtte og hjelp i ditt arbeid fra din nærmeste sjef? | T4: 19. Blir dine arbeidsresultater verdsatt av din nærmeste sjef? | U4: 20. Oppmuntrer din nærmeste sjef deg til å delta i viktige avgjørelser? | V4: 21. Hjelper din nærmeste sjef deg med å utvikle dine ferdigheter? | W4: 22. Føler du at du kan stole på at venner og familie vil støtte deg hvis det blir vanskelig på jobben? | X4: 23. Oppmuntrende og bemyndigende | Y4: 24. Avslappet og behagelig | Z4: 25. Stivbent og regelstyrt | AA4: 26. Setter du pris på å være medlem av arbeidsgruppen? | AB4: 27. Er gruppen din dyktig til å løse problemer? | AC4: 28. Blir de ansatte oppmuntret til å tenke ut måter for å gjøre tingene bedre på, på ditt arbeidssted? | AD4: 29. Er det god nok kommunikasjon i din avdeling? | AE4: 30. Har du lagt merke til forstyrrende konflikter mellom arbeidskollegaer? | AF4: 31. Har du lagt merke til om menn og kvinner blir behandlet ulikt på arbeidsstedet ditt? | AG4: 32. Har du lagt merke til om eldre og yngre arbeidstakere blir behandlet ulikt på arbeidsstedet ditt? | AH4: 33. Får du belønning for velgjort arbeid i din bedrift/virksomhet (penger, oppmuntring)? | AI4: 34. Hvor meget er ledelsen i din bedrift/virksomhet opptatt av den ansattes helse og velvære? | AJ4: 35. Jeg liker å være opptatt av jobben min mesteparten av tiden. | AK4: 36. Den største tilfredsstillelsen i mitt liv kommer fra jobben. | AL4: 37. Føler du denne typen stress nå for tiden?
A5: 1
A6: 2
A7: 3
A8: 4
A9: 5
A10: 6
A11: 7
A12: 8
A13: 9
A14: 10
A15: 11
A16: 12
... A304: 300

Sheet Oppsummering
A1: Oppsummering
A2: Vises først når minst 10 har svart på spørsmålet (veiledningen s. 14).
A4: Nr. | B4: Spørsmål | C4: Antall svar | D4: Middelverdi | E4: Median | F4: Andel 1–2 | G4: Andel 3 | H4: Andel 4–5
A5: 1 | B5: Er arbeidsmengden din ujevn slik at den hoper seg opp? | C5: =COUNT(Svar!B$5:B$304) | D5: =IF(C5<10,"",ROUND(AVERAGE(Svar!B$5:B$304),2)) | E5: =IF(C5<10,"",MEDIAN(Svar!B$5:B$304)) | F5: =IF(C5<10,"",(COUNTIF(Svar!B$5:B$304,1)+COUNTIF(Svar!B$5:B$304,2))/C5) | G5: =IF(C5<10,"",COUNTIF(Svar!B$5:B$304,3)/C5) | H5: =IF(C5<10,"",(COUNTIF(Svar!B$5:B$304,4)+COUNTIF(Svar!B$5:B$304,5))/C5)
A6: 2 | B6: Har du for mye å gjøre? | C6: =COUNT(Svar!C$5:C$304) | D6: =IF(C6<10,"",ROUND(AVERAGE(Svar!C$5:C$304),2)) | E6: =IF(C6<10,"",MEDIAN(Svar!C$5:C$304)) | F6: =IF(C6<10,"",(COUNTIF(Svar!C$5:C$304,1)+COUNTIF(Svar!C$5:C$304,2))/C6) | G6: =IF(C6<10,"",COUNTIF(Svar!C$5:C$304,3)/C6) | H6: =IF(C6<10,"",(COUNTIF(Svar!C$5:C$304,4)+COUNTIF(Svar!C$5:C$304,5))/C6)
A7: 3 | B7: Er arbeidsoppgavene for vanskelige for deg? | C7: =COUNT(Svar!D$5:D$304) | D7: =IF(C7<10,"",ROUND(AVERAGE(Svar!D$5:D$304),2)) | E7: =IF(C7<10,"",MEDIAN(Svar!D$5:D$304)) | F7: =IF(C7<10,"",(COUNTIF(Svar!D$5:D$304,1)+COUNTIF(Svar!D$5:D$304,2))/C7) | G7: =IF(C7<10,"",COUNTIF(Svar!D$5:D$304,3)/C7) | H7: =IF(C7<10,"",(COUNTIF(Svar!D$5:D$304,4)+COUNTIF(Svar!D$5:D$304,5))/C7)
A8: 4 | B8: Utfører du arbeidsoppgaver som du trenger mer opplæring for å gjøre? | C8: =COUNT(Svar!E$5:E$304) | D8: =IF(C8<10,"",ROUND(AVERAGE(Svar!E$5:E$304),2)) | E8: =IF(C8<10,"",MEDIAN(Svar!E$5:E$304)) | F8: =IF(C8<10,"",(COUNTIF(Svar!E$5:E$304,1)+COUNTIF(Svar!E$5:E$304,2))/C8) | G8: =IF(C8<10,"",COUNTIF(Svar!E$5:E$304,3)/C8) | H8: =IF(C8<10,"",(COUNTIF(Svar!E$5:E$304,4)+COUNTIF(Svar!E$5:E$304,5))/C8)
A9: 5 | B9: Er dine spesialkunnskaper og ferdigheter nyttige i arbeidet ditt? | C9: =COUNT(Svar!F$5:F$304) | D9: =IF(C9<10,"",ROUND(AVERAGE(Svar!F$5:F$304),2)) | E9: =IF(C9<10,"",MEDIAN(Svar!F$5:F$304)) | F9: =IF(C9<10,"",(COUNTIF(Svar!F$5:F$304,1)+COUNTIF(Svar!F$5:F$304,2))/C9) | G9: =IF(C9<10,"",COUNTIF(Svar!F$5:F$304,3)/C9) | H9: =IF(C9<10,"",(COUNTIF(Svar!F$5:F$304,4)+COUNTIF(Svar!F$5:F$304,5))/C9)
A10: 6 | B10: Er arbeidet ditt utfordrende på en positiv måte? | C10: =COUNT(Svar!G$5:G$304) | D10: =IF(C10<10,"",ROUND(AVERAGE(Svar!G$5:G$304),2)) | E10: =IF(C10<10,"",MEDIAN(Svar!G$5:G$304)) | F10: =IF(C10<10,"",(COUNTIF(Svar!G$5:G$304,1)+COUNTIF(Svar!G$5:G$304,2))/C10) | G10: =IF(C10<10,"",COUNTIF(Svar!G$5:G$304,3)/C10) | H10: =IF(C10<10,"",(COUNTIF(Svar!G$5:G$304,4)+COUNTIF(Svar!G$5:G$304,5))/C10)
A11: 7 | B11: Er det fastsatt klare mål for din jobb? | C11: =COUNT(Svar!H$5:H$304) | D11: =IF(C11<10,"",ROUND(AVERAGE(Svar!H$5:H$304),2)) | E11: =IF(C11<10,"",MEDIAN(Svar!H$5:H$304)) | F11: =IF(C11<10,"",(COUNTIF(Svar!H$5:H$304,1)+COUNTIF(Svar!H$5:H$304,2))/C11) | G11: =IF(C11<10,"",COUNTIF(Svar!H$5:H$304,3)/C11) | H11: =IF(C11<10,"",(COUNTIF(Svar!H$5:H$304,4)+COUNTIF(Svar!H$5:H$304,5))/C11)
A12: 8 | B12: Vet du nøyaktig hva som forventes av deg i jobben? | C12: =COUNT(Svar!I$5:I$304) | D12: =IF(C12<10,"",ROUND(AVERAGE(Svar!I$5:I$304),2)) | E12: =IF(C12<10,"",MEDIAN(Svar!I$5:I$304)) | F12: =IF(C12<10,"",(COUNTIF(Svar!I$5:I$304,1)+COUNTIF(Svar!I$5:I$304,2))/C12) | G12: =IF(C12<10,"",COUNTIF(Svar!I$5:I$304,3)/C12) | H12: =IF(C12<10,"",(COUNTIF(Svar!I$5:I$304,4)+COUNTIF(Svar!I$5:I$304,5))/C12)
A13: 9 | B13: Mottar du motstridende forespørsler fra to eller flere personer? | C13: =COUNT(Svar!J$5:J$304) | D13: =IF(C13<10,"",ROUND(AVERAGE(Svar!J$5:J$304),2)) | E13: =IF(C13<10,"",MEDIAN(Svar!J$5:J$304)) | F13: =IF(C13<10,"",(COUNTIF(Svar!J$5:J$304,1)+COUNTIF(Svar!J$5:J$304,2))/C13) | G13: =IF(C13<10,"",COUNTIF(Svar!J$5:J$304,3)/C13) | H13: =IF(C13<10,"",(COUNTIF(Svar!J$5:J$304,4)+COUNTIF(Svar!J$5:J$304,5))/C13)
A14: 10 | B14: Kan du påvirke mengden av arbeid som blir tildelt deg? | C14: =COUNT(Svar!K$5:K$304) | D14: =IF(C14<10,"",ROUND(AVERAGE(Svar!K$5:K$304),2)) | E14: =IF(C14<10,"",MEDIAN(Svar!K$5:K$304)) | F14: =IF(C14<10,"",(COUNTIF(Svar!K$5:K$304,1)+COUNTIF(Svar!K$5:K$304,2))/C14) | G14: =IF(C14<10,"",COUNTIF(Svar!K$5:K$304,3)/C14) | H14: =IF(C14<10,"",(COUNTIF(Svar!K$5:K$304,4)+COUNTIF(Svar!K$5:K$304,5))/C14)
A15: 11 | B15: Kan du selv bestemme ditt arbeidstempo? | C15: =COUNT(Svar!L$5:L$304) | D15: =IF(C15<10,"",ROUND(AVERAGE(Svar!L$5:L$304),2)) | E15: =IF(C15<10,"",MEDIAN(Svar!L$5:L$304)) | F15: =IF(C15<10,"",(COUNTIF(Svar!L$5:L$304,1)+COUNTIF(Svar!L$5:L$304,2))/C15) | G15: =IF(C15<10,"",COUNTIF(Svar!L$5:L$304,3)/C15) | H15: =IF(C15<10,"",(COUNTIF(Svar!L$5:L$304,4)+COUNTIF(Svar!L$5:L$304,5))/C15)
A16: 12 | B16: Kan du selv bestemme når du skal ta pauser? | C16: =COUNT(Svar!M$5:M$304) | D16: =IF(C16<10,"",ROUND(AVERAGE(Svar!M$5:M$304),2)) | E16: =IF(C16<10,"",MEDIAN(Svar!M$5:M$304)) | F16: =IF(C16<10,"",(COUNTIF(Svar!M$5:M$304,1)+COUNTIF(Svar!M$5:M$304,2))/C16) | G16: =IF(C16<10,"",COUNTIF(Svar!M$5:M$304,3)/C16) | H16: =IF(C16<10,"",(COUNTIF(Svar!M$5:M$304,4)+COUNTIF(Svar!M$5:M$304,5))/C16)
A17: 13 | B17: Kan du påvirke beslutninger som er viktige for ditt arbeid? | C17: =COUNT(Svar!N$5:N$304) | D17: =IF(C17<10,"",ROUND(AVERAGE(Svar!N$5:N$304),2)) | E17: =IF(C17<10,"",MEDIAN(Svar!N$5:N$304)) | F17: =IF(C17<10,"",(COUNTIF(Svar!N$5:N$304,1)+COUNTIF(Svar!N$5:N$304,2))/C17) | G17: =IF(C17<10,"",COUNTIF(Svar!N$5:N$304,3)/C17) | H17: =IF(C17<10,"",(COUNTIF(Svar!N$5:N$304,4)+COUNTIF(Svar!N$5:N$304,5))/C17)
A18: 14 | B18: Vet du hva slags oppgaver du kan få en måned frem i tiden? | C18: =COUNT(Svar!O$5:O$304) | D18: =IF(C18<10,"",ROUND(AVERAGE(Svar!O$5:O$304),2)) | E18: =IF(C18<10,"",MEDIAN(Svar!O$5:O$304)) | F18: =IF(C18<10,"",(COUNTIF(Svar!O$5:O$304,1)+COUNTIF(Svar!O$5:O$304,2))/C18) | G18: =IF(C18<10,"",COUNTIF(Svar!O$5:O$304,3)/C18) | H18: =IF(C18<10,"",(COUNTIF(Svar!O$5:O$304,4)+COUNTIF(Svar!O$5:O$304,5))/C18)
A19: 15 | B19: Går det rykter om forandringer på din arbeidsplass? | C19: =COUNT(Svar!P$5:P$304) | D19: =IF(C19<10,"",ROUND(AVERAGE(Svar!P$5:P$304),2)) | E19: =IF(C19<10,"",MEDIAN(Svar!P$5:P$304)) | F19: =IF(C19<10,"",(COUNTIF(Svar!P$5:P$304,1)+COUNTIF(Svar!P$5:P$304,2))/C19) | G19: =IF(C19<10,"",COUNTIF(Svar!P$5:P$304,3)/C19) | H19: =IF(C19<10,"",(COUNTIF(Svar!P$5:P$304,4)+COUNTIF(Svar!P$5:P$304,5))/C19)
A20: 16 | B20: Er du fornøyd med din evne til å løse problemer som dukker opp i arbeidet? | C20: =COUNT(Svar!Q$5:Q$304) | D20: =IF(C20<10,"",ROUND(AVERAGE(Svar!Q$5:Q$304),2)) | E20: =IF(C20<10,"",MEDIAN(Svar!Q$5:Q$304)) | F20: =IF(C20<10,"",(COUNTIF(Svar!Q$5:Q$304,1)+COUNTIF(Svar!Q$5:Q$304,2))/C20) | G20: =IF(C20<10,"",COUNTIF(Svar!Q$5:Q$304,3)/C20) | H20: =IF(C20<10,"",(COUNTIF(Svar!Q$5:Q$304,4)+COUNTIF(Svar!Q$5:Q$304,5))/C20)
A21: 17 | B21: Om du trenger det, kan du få støtte og hjelp i ditt arbeid fra dine kollegaer? | C21: =COUNT(Svar!R$5:R$304) | D21: =IF(C21<10,"",ROUND(AVERAGE(Svar!R$5:R$304),2)) | E21: =IF(C21<10,"",MEDIAN(Svar!R$5:R$304)) | F21: =IF(C21<10,"",(COUNTIF(Svar!R$5:R$304,1)+COUNTIF(Svar!R$5:R$304,2))/C21) | G21: =IF(C21<10,"",COUNTIF(Svar!R$5:R$304,3)/C21) | H21: =IF(C21<10,"",(COUNTIF(Svar!R$5:R$304,4)+COUNTIF(Svar!R$5:R$304,5))/C21)
A22: 18 | B22: Om du trenger det, kan du få støtte og hjelp i ditt arbeid fra din nærmeste sjef? | C22: =COUNT(Svar!S$5:S$304) | D22: =IF(C22<10,"",ROUND(AVERAGE(Svar!S$5:S$304),2)) | E22: =IF(C22<10,"",MEDIAN(Svar!S$5:S$304)) | F22: =IF(C22<10,"",(COUNTIF(Svar!S$5:S$304,1)+COUNTIF(Svar!S$5:S$304,2))/C22) | G22: =IF(C22<10,"",COUNTIF(Svar!S$5:S$304,3)/C22) | H22: =IF(C22<10,"",(COUNTIF(Svar!S$5:S$304,4)+COUNTIF(Svar!S$5:S$304,5))/C22)
A23: 19 | B23: Blir dine arbeidsresultater verdsatt av din nærmeste sjef? | C23: =COUNT(Svar!T$5:T$304) | D23: =IF(C23<10,"",ROUND(AVERAGE(Svar!T$5:T$304),2)) | E23: =IF(C23<10,"",MEDIAN(Svar!T$5:T$304)) | F23: =IF(C23<10,"",(COUNTIF(Svar!T$5:T$304,1)+COUNTIF(Svar!T$5:T$304,2))/C23) | G23: =IF(C23<10,"",COUNTIF(Svar!T$5:T$304,3)/C23) | H23: =IF(C23<10,"",(COUNTIF(Svar!T$5:T$304,4)+COUNTIF(Svar!T$5:T$304,5))/C23)
A24: 20 | B24: Oppmuntrer din nærmeste sjef deg til å delta i viktige avgjørelser? | C24: =COUNT(Svar!U$5:U$304) | D24: =IF(C24<10,"",ROUND(AVERAGE(Svar!U$5:U$304),2)) | E24: =IF(C24<10,"",MEDIAN(Svar!U$5:U$304)) | F24: =IF(C24<10,"",(COUNTIF(Svar!U$5:U$304,1)+COUNTIF(Svar!U$5:U$304,2))/C24) | G24: =IF(C24<10,"",COUNTIF(Svar!U$5:U$304,3)/C24) | H24: =IF(C24<10,"",(COUNTIF(Svar!U$5:U$304,4)+COUNTIF(Svar!U$5:U$304,5))/C24)
A25: 21 | B25: Hjelper din nærmeste sjef deg med å utvikle dine ferdigheter? | C25: =COUNT(Svar!V$5:V$304) | D25: =IF(C25<10,"",ROUND(AVERAGE(Svar!V$5:V$304),2)) | E25: =IF(C25<10,"",MEDIAN(Svar!V$5:V$304)) | F25: =IF(C25<10,"",(COUNTIF(Svar!V$5:V$304,1)+COUNTIF(Svar!V$5:V$304,2))/C25) | G25: =IF(C25<10,"",COUNTIF(Svar!V$5:V$304,3)/C25) | H25: =IF(C25<10,"",(COUNTIF(Svar!V$5:V$304,4)+COUNTIF(Svar!V$5:V$304,5))/C25)
A26: 22 | B26: Føler du at du kan stole på at venner og familie vil støtte deg hvis det blir vanskelig på jobben? | C26: =COUNT(Svar!W$5:W$304) | D26: =IF(C26<10,"",ROUND(AVERAGE(Svar!W$5:W$304),2)) | E26: =IF(C26<10,"",MEDIAN(Svar!W$5:W$304)) | F26: =IF(C26<10,"",(COUNTIF(Svar!W$5:W$304,1)+COUNTIF(Svar!W$5:W$304,2))/C26) | G26: =IF(C26<10,"",COUNTIF(Svar!W$5:W$304,3)/C26) | H26: =IF(C26<10,"",(COUNTIF(Svar!W$5:W$304,4)+COUNTIF(Svar!W$5:W$304,5))/C26)
A27: 23 | B27: Hvordan er klimaet i din arbeidsenhet? Oppmuntrende og bemyndigende | C27: =COUNT(Svar!X$5:X$304) | D27: =IF(C27<10,"",ROUND(AVERAGE(Svar!X$5:X$304),2)) | E27: =IF(C27<10,"",MEDIAN(Svar!X$5:X$304)) | F27: =IF(C27<10,"",(COUNTIF(Svar!X$5:X$304,1)+COUNTIF(Svar!X$5:X$304,2))/C27) | G27: =IF(C27<10,"",COUNTIF(Svar!X$5:X$304,3)/C27) | H27: =IF(C27<10,"",(COUNTIF(Svar!X$5:X$304,4)+COUNTIF(Svar!X$5:X$304,5))/C27)
A28: 24 | B28: Hvordan er klimaet i din arbeidsenhet? Avslappet og behagelig | C28: =COUNT(Svar!Y$5:Y$304) | D28: =IF(C28<10,"",ROUND(AVERAGE(Svar!Y$5:Y$304),2)) | E28: =IF(C28<10,"",MEDIAN(Svar!Y$5:Y$304)) | F28: =IF(C28<10,"",(COUNTIF(Svar!Y$5:Y$304,1)+COUNTIF(Svar!Y$5:Y$304,2))/C28) | G28: =IF(C28<10,"",COUNTIF(Svar!Y$5:Y$304,3)/C28) | H28: =IF(C28<10,"",(COUNTIF(Svar!Y$5:Y$304,4)+COUNTIF(Svar!Y$5:Y$304,5))/C28)
A29: 25 | B29: Hvordan er klimaet i din arbeidsenhet? Stivbent og regelstyrt | C29: =COUNT(Svar!Z$5:Z$304) | D29: =IF(C29<10,"",ROUND(AVERAGE(Svar!Z$5:Z$304),2)) | E29: =IF(C29<10,"",MEDIAN(Svar!Z$5:Z$304)) | F29: =IF(C29<10,"",(COUNTIF(Svar!Z$5:Z$304,1)+COUNTIF(Svar!Z$5:Z$304,2))/C29) | G29: =IF(C29<10,"",COUNTIF(Svar!Z$5:Z$304,3)/C29) | H29: =IF(C29<10,"",(COUNTIF(Svar!Z$5:Z$304,4)+COUNTIF(Svar!Z$5:Z$304,5))/C29)
A30: 26 | B30: Setter du pris på å være medlem av arbeidsgruppen? | C30: =COUNT(Svar!AA$5:AA$304) | D30: =IF(C30<10,"",ROUND(AVERAGE(Svar!AA$5:AA$304),2)) | E30: =IF(C30<10,"",MEDIAN(Svar!AA$5:AA$304)) | F30: =IF(C30<10,"",(COUNTIF(Svar!AA$5:AA$304,1)+COUNTIF(Svar!AA$5:AA$304,2))/C30) | G30: =IF(C30<10,"",COUNTIF(Svar!AA$5:AA$304,3)/C30) | H30: =IF(C30<10,"",(COUNTIF(Svar!AA$5:AA$304,4)+COUNTIF(Svar!AA$5:AA$304,5))/C30)
A31: 27 | B31: Er gruppen din dyktig til å løse problemer? | C31: =COUNT(Svar!AB$5:AB$304) | D31: =IF(C31<10,"",ROUND(AVERAGE(Svar!AB$5:AB$304),2)) | E31: =IF(C31<10,"",MEDIAN(Svar!AB$5:AB$304)) | F31: =IF(C31<10,"",(COUNTIF(Svar!AB$5:AB$304,1)+COUNTIF(Svar!AB$5:AB$304,2))/C31) | G31: =IF(C31<10,"",COUNTIF(Svar!AB$5:AB$304,3)/C31) | H31: =IF(C31<10,"",(COUNTIF(Svar!AB$5:AB$304,4)+COUNTIF(Svar!AB$5:AB$304,5))/C31)
A32: 28 | B32: Blir de ansatte oppmuntret til å tenke ut måter for å gjøre tingene bedre på, på ditt arbeidssted? | C32: =COUNT(Svar!AC$5:AC$304) | D32: =IF(C32<10,"",ROUND(AVERAGE(Svar!AC$5:AC$304),2)) | E32: =IF(C32<10,"",MEDIAN(Svar!AC$5:AC$304)) | F32: =IF(C32<10,"",(COUNTIF(Svar!AC$5:AC$304,1)+COUNTIF(Svar!AC$5:AC$304,2))/C32) | G32: =IF(C32<10,"",COUNTIF(Svar!AC$5:AC$304,3)/C32) | H32: =IF(C32<10,"",(COUNTIF(Svar!AC$5:AC$304,4)+COUNTIF(Svar!AC$5:AC$304,5))/C32)
A33: 29 | B33: Er det god nok kommunikasjon i din avdeling? | C33: =COUNT(Svar!AD$5:AD$304) | D33: =IF(C33<10,"",ROUND(AVERAGE(Svar!AD$5:AD$304),2)) | E33: =IF(C33<10,"",MEDIAN(Svar!AD$5:AD$304)) | F33: =IF(C33<10,"",(COUNTIF(Svar!AD$5:AD$304,1)+COUNTIF(Svar!AD$5:AD$304,2))/C33) | G33: =IF(C33<10,"",COUNTIF(Svar!AD$5:AD$304,3)/C33) | H33: =IF(C33<10,"",(COUNTIF(Svar!AD$5:AD$304,4)+COUNTIF(Svar!AD$5:AD$304,5))/C33)
A34: 30 | B34: Har du lagt merke til forstyrrende konflikter mellom arbeidskollegaer? | C34: =COUNT(Svar!AE$5:AE$304) | D34: =IF(C34<10,"",ROUND(AVERAGE(Svar!AE$5:AE$304),2)) | E34: =IF(C34<10,"",MEDIAN(Svar!AE$5:AE$304)) | F34: =IF(C34<10,"",(COUNTIF(Svar!AE$5:AE$304,1)+COUNTIF(Svar!AE$5:AE$304,2))/C34) | G34: =IF(C34<10,"",COUNTIF(Svar!AE$5:AE$304,3)/C34) | H34: =IF(C34<10,"",(COUNTIF(Svar!AE$5:AE$304,4)+COUNTIF(Svar!AE$5:AE$304,5))/C34)
A35: 31 | B35: Har du lagt merke til om menn og kvinner blir behandlet ulikt på arbeidsstedet ditt? | C35: =COUNT(Svar!AF$5:AF$304) | D35: =IF(C35<10,"",ROUND(AVERAGE(Svar!AF$5:AF$304),2)) | E35: =IF(C35<10,"",MEDIAN(Svar!AF$5:AF$304)) | F35: =IF(C35<10,"",(COUNTIF(Svar!AF$5:AF$304,1)+COUNTIF(Svar!AF$5:AF$304,2))/C35) | G35: =IF(C35<10,"",COUNTIF(Svar!AF$5:AF$304,3)/C35) | H35: =IF(C35<10,"",(COUNTIF(Svar!AF$5:AF$304,4)+COUNTIF(Svar!AF$5:AF$304,5))/C35)
A36: 32 | B36: Har du lagt merke til om eldre og yngre arbeidstakere blir behandlet ulikt på arbeidsstedet ditt? | C36: =COUNT(Svar!AG$5:AG$304) | D36: =IF(C36<10,"",ROUND(AVERAGE(Svar!AG$5:AG$304),2)) | E36: =IF(C36<10,"",MEDIAN(Svar!AG$5:AG$304)) | F36: =IF(C36<10,"",(COUNTIF(Svar!AG$5:AG$304,1)+COUNTIF(Svar!AG$5:AG$304,2))/C36) | G36: =IF(C36<10,"",COUNTIF(Svar!AG$5:AG$304,3)/C36) | H36: =IF(C36<10,"",(COUNTIF(Svar!AG$5:AG$304,4)+COUNTIF(Svar!AG$5:AG$304,5))/C36)
A37: 33 | B37: Får du belønning for velgjort arbeid i din bedrift/virksomhet (penger, oppmuntring)? | C37: =COUNT(Svar!AH$5:AH$304) | D37: =IF(C37<10,"",ROUND(AVERAGE(Svar!AH$5:AH$304),2)) | E37: =IF(C37<10,"",MEDIAN(Svar!AH$5:AH$304)) | F37: =IF(C37<10,"",(COUNTIF(Svar!AH$5:AH$304,1)+COUNTIF(Svar!AH$5:AH$304,2))/C37) | G37: =IF(C37<10,"",COUNTIF(Svar!AH$5:AH$304,3)/C37) | H37: =IF(C37<10,"",(COUNTIF(Svar!AH$5:AH$304,4)+COUNTIF(Svar!AH$5:AH$304,5))/C37)
A38: 34 | B38: Hvor meget er ledelsen i din bedrift/virksomhet opptatt av den ansattes helse og velvære? | C38: =COUNT(Svar!AI$5:AI$304) | D38: =IF(C38<10,"",ROUND(AVERAGE(Svar!AI$5:AI$304),2)) | E38: =IF(C38<10,"",MEDIAN(Svar!AI$5:AI$304)) | F38: =IF(C38<10,"",(COUNTIF(Svar!AI$5:AI$304,1)+COUNTIF(Svar!AI$5:AI$304,2))/C38) | G38: =IF(C38<10,"",COUNTIF(Svar!AI$5:AI$304,3)/C38) | H38: =IF(C38<10,"",(COUNTIF(Svar!AI$5:AI$304,4)+COUNTIF(Svar!AI$5:AI$304,5))/C38)
A39: 35 | B39: Jeg liker å være opptatt av jobben min mesteparten av tiden. | C39: =COUNT(Svar!AJ$5:AJ$304) | D39: =IF(C39<10,"",ROUND(AVERAGE(Svar!AJ$5:AJ$304),2)) | E39: =IF(C39<10,"",MEDIAN(Svar!AJ$5:AJ$304)) | F39: =IF(C39<10,"",(COUNTIF(Svar!AJ$5:AJ$304,1)+COUNTIF(Svar!AJ$5:AJ$304,2))/C39) | G39: =IF(C39<10,"",COUNTIF(Svar!AJ$5:AJ$304,3)/C39) | H39: =IF(C39<10,"",(COUNTIF(Svar!AJ$5:AJ$304,4)+COUNTIF(Svar!AJ$5:AJ$304,5))/C39)
A40: 36 | B40: Den største tilfredsstillelsen i mitt liv kommer fra jobben. | C40: =COUNT(Svar!AK$5:AK$304) | D40: =IF(C40<10,"",ROUND(AVERAGE(Svar!AK$5:AK$304),2)) | E40: =IF(C40<10,"",MEDIAN(Svar!AK$5:AK$304)) | F40: =IF(C40<10,"",(COUNTIF(Svar!AK$5:AK$304,1)+COUNTIF(Svar!AK$5:AK$304,2))/C40) | G40: =IF(C40<10,"",COUNTIF(Svar!AK$5:AK$304,3)/C40) | H40: =IF(C40<10,"",(COUNTIF(Svar!AK$5:AK$304,4)+COUNTIF(Svar!AK$5:AK$304,5))/C40)
A41: 37 | B41: Føler du denne typen stress nå for tiden? | C41: =COUNT(Svar!AL$5:AL$304) | D41: =IF(C41<10,"",ROUND(AVERAGE(Svar!AL$5:AL$304),2)) | E41: =IF(C41<10,"",MEDIAN(Svar!AL$5:AL$304)) | F41: =IF(C41<10,"",(COUNTIF(Svar!AL$5:AL$304,1)+COUNTIF(Svar!AL$5:AL$304,2))/C41) | G41: =IF(C41<10,"",COUNTIF(Svar!AL$5:AL$304,3)/C41) | H41: =IF(C41<10,"",(COUNTIF(Svar!AL$5:AL$304,4)+COUNTIF(Svar!AL$5:AL$304,5))/C41)
...
